Workbook

Sheet Unit Prices
A2: HASSAN ALLAM CONSTRUCTION
A3: SUPPORT DIVISION
A4: FORMWORK AND SCAFFOLDING DEPARTMENT
A5: 10th OF RAMADAN SECTOR
A7: FORMWORK AND SCAFFOLDING ITEMS PRICES LIST
A8: No | B8: ASSET CODE | C8: FULL SERIAL | D8: ITEMS NAME | E8: INTERNAL HIRE RATE | F8: EXTERNAL HIRE RATE | G8: UNIT PURCHASE PRICE
A9: 1 | B9: ='[1]FWSCAF-Master Data 2021'!B9 -> CK0021 | C9: ='[1]FWSCAF-Master Data 2021'!C9 -> 14.80.02.19.06.05.00.000001 | D9: ='[1]FWSCAF-Master Data 2021'!D9 -> cuplock Vertical 0.5M | E9: ='[1]FWSCAF-Master Data 2021'!E9 -> 2.55645 | F9: ='[1]FWSCAF-Master Data 2021'!F9 -> 2.691 | G9: ='[1]FWSCAF-Master Data 2021'!G9 -> 90.25
A10: 2 | B10: ='[1]FWSCAF-Master Data 2021'!B10 -> CK0018 | C10: ='[1]FWSCAF-Master Data 2021'!C10 -> 14.80.02.19.06.01.00.000001 | D10: ='[1]FWSCAF-Master Data 2021'!D10 -> cuplock Vertical 1M | E10: ='[1]FWSCAF-Master Data 2021'!E10 -> 5.119075 | F10: ='[1]FWSCAF-Master Data 2021'!F10 -> 5.3885 | G10: ='[1]FWSCAF-Master Data 2021'!G10 -> 179
A11: 3 | B11: ='[1]FWSCAF-Master Data 2021'!B11 -> CK0022 | C11: ='[1]FWSCAF-Master Data 2021'!C11 -> 14.80.02.19.06.13.00.000001 | D11: ='[1]FWSCAF-Master Data 2021'!D11 -> cuplock Vertical 1.3M | E11: ='[1]FWSCAF-Master Data 2021'!E11 -> 7.020975 | F11: ='[1]FWSCAF-Master Data 2021'!F11 -> 7.3905 | G11: ='[1]FWSCAF-Master Data 2021'!G11 -> 255
A12: 4 | B12: ='[1]FWSCAF-Master Data 2021'!B12 -> CK0023 | C12: ='[1]FWSCAF-Master Data 2021'!C12 -> 14.80.02.19.06.15.00.000001 | D12: ='[1]FWSCAF-Master Data 2021'!D12 -> cuplock Vertical 1.5M | E12: ='[1]FWSCAF-Master Data 2021'!E12 -> 7.675525 | F12: ='[1]FWSCAF-Master Data 2021'!F12 -> 8.0795 | G12: ='[1]FWSCAF-Master Data 2021'!G12 -> 268.25
A13: 5 | B13: ='[1]FWSCAF-Master Data 2021'!B13 -> CK0024 | C13: ='[1]FWSCAF-Master Data 2021'!C13 -> 14.80.02.19.06.18.00.000001 | D13: ='[1]FWSCAF-Master Data 2021'!D13 -> cuplock Vertical 1.8M | E13: ='[1]FWSCAF-Master Data 2021'!E13 -> 9.577425 | F13: ='[1]FWSCAF-Master Data 2021'!F13 -> 10.0815 | G13: ='[1]FWSCAF-Master Data 2021'!G13 -> 325
A14: 6 | B14: ='[1]FWSCAF-Master Data 2021'!B14 -> CK0019 | C14: ='[1]FWSCAF-Master Data 2021'!C14 -> 14.80.02.19.06.02.00.000001 | D14: ='[1]FWSCAF-Master Data 2021'!D14 -> cuplock Vertical 2M | E14: ='[1]FWSCAF-Master Data 2021'!E14 -> 10.231975 | F14: ='[1]FWSCAF-Master Data 2021'!F14 -> 10.7705 | G14: ='[1]FWSCAF-Master Data 2021'!G14 -> 357
A15: 7 | B15: ='[1]FWSCAF-Master Data 2021'!B15 -> CK0025 | C15: ='[1]FWSCAF-Master Data 2021'!C15 -> 14.80.02.19.06.23.00.000001 | D15: ='[1]FWSCAF-Master Data 2021'!D15 -> cuplock Vertical 2.3M | E15: ='[1]FWSCAF-Master Data 2021'!E15 -> 12.133875 | F15: ='[1]FWSCAF-Master Data 2021'!F15 -> 12.7725 | G15: ='[1]FWSCAF-Master Data 2021'!G15 -> 425
A16: 8 | B16: ='[1]FWSCAF-Master Data 2021'!B16 -> CK0026 | C16: ='[1]FWSCAF-Master Data 2021'!C16 -> 14.80.02.19.06.25.00.000001 | D16: ='[1]FWSCAF-Master Data 2021'!D16 -> cuplock Vertical 2.5M | E16: ='[1]FWSCAF-Master Data 2021'!E16 -> 12.7946 | F16: ='[1]FWSCAF-Master Data 2021'!F16 -> 13.468 | G16: ='[1]FWSCAF-Master Data 2021'!G16 -> 439.5
A17: 9 | B17: ='[1]FWSCAF-Master Data 2021'!B17 -> CK0027 | C17: ='[1]FWSCAF-Master Data 2021'!C17 -> 14.80.02.19.06.28.00.000001 | D17: ='[1]FWSCAF-Master Data 2021'!D17 -> cuplock Vertical 2.8M | E17: ='[1]FWSCAF-Master Data 2021'!E17 -> 14.028438 | F17: ='[1]FWSCAF-Master Data 2021'!F17 -> 18.2 | G17: ='[1]FWSCAF-Master Data 2021'!G17 -> 520
A18: 10 | B18: ='[1]FWSCAF-Master Data 2021'!B18 -> CK0020 | C18: ='[1]FWSCAF-Master Data 2021'!C18 -> 14.80.02.19.06.03.00.000001 | D18: ='[1]FWSCAF-Master Data 2021'!D18 -> cuplock Vertical 3M | E18: ='[1]FWSCAF-Master Data 2021'!E18 -> 14.028438 | F18: ='[1]FWSCAF-Master Data 2021'!F18 -> 16.159 | G18: ='[1]FWSCAF-Master Data 2021'!G18 -> 535.5
A19: 11 | B19: ='[1]FWSCAF-Master Data 2021'!B19 -> CL0001 | C19: ='[1]FWSCAF-Master Data 2021'!C19 -> 14.80.50.24.01.00.00.000001 | D19: ='[1]FWSCAF-Master Data 2021'!D19 -> cuplock Spigot | E19: ='[1]FWSCAF-Master Data 2021'!E19 -> 1.275 | F19: ='[1]FWSCAF-Master Data 2021'!F19 -> 1.5 | G19: ='[1]FWSCAF-Master Data 2021'!G19 -> 22
A20: 12 | B20: ='[1]FWSCAF-Master Data 2021'!B20 -> CK0006 | C20: ='[1]FWSCAF-Master Data 2021'!C20 -> 14.80.02.19.04.04.00.000001 | D20: ='[1]FWSCAF-Master Data 2021'!D20 -> cuplock Ledger 0.4M | E20: ='[1]FWSCAF-Master Data 2021'!E20 -> 1.71665 | F20: ='[1]FWSCAF-Master Data 2021'!F20 -> 1.807 | G20: ='[1]FWSCAF-Master Data 2021'!G20 -> 65
... A1045: 1037 | B1045: ='[1]FWSCAF-Master Data 2021'!B1045 -> 0 | C1045: ='[1]FWSCAF-Master Data 2021'!C1045 -> 0 | D1045: ='[1]FWSCAF-Master Data 2021'!D1045 -> #N/A | E1045: ='[1]FWSCAF-Master Data 2021'!E1045 -> 0 | F1045: ='[1]FWSCAF-Master Data 2021'!F1045 -> 0 | G1045: ='[1]FWSCAF-Master Data 2021'!G1045 -> 0

Sheet PR-Format
A1: Project Name: | D1: Slab | E1: 0 | F1: =$C$6*E1 -> 0 | I1: =E1 -> 0 | J1: =E1 -> 0 | P1: =I1 -> 0
D2: Walls and Colums | E2: 0 | F2: =$C$6*E2 -> 0 | I2: =E2 -> 0 | J2: =E2 -> 0 | P2: =I2 -> 0
A3: PR# No: | D3: Scaffolding | E3: 0 | F3: =$C$6*E3 -> 0 | I3: =E3 -> 0 | J3: =E3 -> 0 | P3: =I3 -> 0
A4: PR# Date: | D4: Safety | E4: 0 | F4: =$C$6*E4 -> 0 | I4: =E4 -> 0 | J4: =E4 -> 0 | M4: Return Qty | P4: =I4 -> 0
A5: PR# For: | D5: Recived/Transfer Date:
A6: Area: | D6: Store Voucher No:
A8: No | B8: ASSET CODE | C8: FULL SERIAL | D8: ITEMS NAME | E8: Req Qty | I8: Send Qty | J8: Remain Qty | K8: Remarks | P8: T.Return
A9: 1 | B9: ='Unit Prices'!B9 -> CK0021 | C9: ='Unit Prices'!C9 -> 14.80.02.19.06.05.00.000001 | D9: ='Unit Prices'!D9 -> cuplock Vertical 0.5M | I9: =SUM(F9:H9) -> 0 | J9: =E9-I9 -> 0 | P9: =SUM(M9:O9) -> 0
A10: 2 | B10: ='Unit Prices'!B10 -> CK0018 | C10: ='Unit Prices'!C10 -> 14.80.02.19.06.01.00.000001 | D10: ='Unit Prices'!D10 -> cuplock Vertical 1M | I10: =SUM(F10:H10) -> 0 | J10: =E10-I10 -> 0 | P10: =SUM(M10:O10) -> 0
A11: 3 | B11: ='Unit Prices'!B11 -> CK0022 | C11: ='Unit Prices'!C11 -> 14.80.02.19.06.13.00.000001 | D11: ='Unit Prices'!D11 -> cuplock Vertical 1.3M | I11: =SUM(F11:H11) -> 0 | J11: =E11-I11 -> 0 | P11: =SUM(M11:O11) -> 0
A12: 4 | B12: ='Unit Prices'!B12 -> CK0023 | C12: ='Unit Prices'!C12 -> 14.80.02.19.06.15.00.000001 | D12: ='Unit Prices'!D12 -> cuplock Vertical 1.5M | I12: =SUM(F12:H12) -> 0 | J12: =E12-I12 -> 0 | P12: =SUM(M12:O12) -> 0
A13: 5 | B13: ='Unit Prices'!B13 -> CK0024 | C13: ='Unit Prices'!C13 -> 14.80.02.19.06.18.00.000001 | D13: ='Unit Prices'!D13 -> cuplock Vertical 1.8M | I13: =SUM(F13:H13) -> 0 | J13: =E13-I13 -> 0 | P13: =SUM(M13:O13) -> 0
A14: 6 | B14: ='Unit Prices'!B14 -> CK0019 | C14: ='Unit Prices'!C14 -> 14.80.02.19.06.02.00.000001 | D14: ='Unit Prices'!D14 -> cuplock Vertical 2M | I14: =SUM(F14:H14) -> 0 | J14: =E14-I14 -> 0 | P14: =SUM(M14:O14) -> 0
A15: 7 | B15: ='Unit Prices'!B15 -> CK0025 | C15: ='Unit Prices'!C15 -> 14.80.02.19.06.23.00.000001 | D15: ='Unit Prices'!D15 -> cuplock Vertical 2.3M | I15: =SUM(F15:H15) -> 0 | J15: =E15-I15 -> 0 | P15: =SUM(M15:O15) -> 0
A16: 8 | B16: ='Unit Prices'!B16 -> CK0026 | C16: ='Unit Prices'!C16 -> 14.80.02.19.06.25.00.000001 | D16: ='Unit Prices'!D16 -> cuplock Vertical 2.5M | I16: =SUM(F16:H16) -> 0 | J16: =E16-I16 -> 0 | P16: =SUM(M16:O16) -> 0
A17: 9 | B17: ='Unit Prices'!B17 -> CK0027 | C17: ='Unit Prices'!C17 -> 14.80.02.19.06.28.00.000001 | D17: ='Unit Prices'!D17 -> cuplock Vertical 2.8M | I17: =SUM(F17:H17) -> 0 | J17: =E17-I17 -> 0 | P17: =SUM(M17:O17) -> 0
A18: 10 | B18: ='Unit Prices'!B18 -> CK0020 | C18: ='Unit Prices'!C18 -> 14.80.02.19.06.03.00.000001 | D18: ='Unit Prices'!D18 -> cuplock Vertical 3M | I18: =SUM(F18:H18) -> 0 | J18: =E18-I18 -> 0 | P18: =SUM(M18:O18) -> 0
A19: 11 | B19: ='Unit Prices'!B19 -> CL0001 | C19: ='Unit Prices'!C19 -> 14.80.50.24.01.00.00.000001 | D19: ='Unit Prices'!D19 -> cuplock Spigot | I19: =SUM(F19:H19) -> 0 | J19: =E19-I19 -> 0 | P19: =SUM(M19:O19) -> 0
A20: 12 | B20: ='Unit Prices'!B20 -> CK0006 | C20: ='Unit Prices'!C20 -> 14.80.02.19.04.04.00.000001 | D20: ='Unit Prices'!D20 -> cuplock Ledger 0.4M | I20: =SUM(F20:H20) -> 0 | J20: =E20-I20 -> 0 | P20: =SUM(M20:O20) -> 0
... A758: 750 | B758: ='Unit Prices'!B758 -> 0 | C758: ='Unit Prices'!C758 -> 0 | D758: ='Unit Prices'!D758 -> #N/A | I758: =SUM(F758:H758) -> 0 | J758: =E758-I758 -> 0 | P758: =SUM(M758:O758) -> 0

Sheet 9400015894 PONEERS
A1: Project Name: | D1: Slab | E1: 1 | F1: =$C$6*E1 -> 0 | X1: =E1 -> 1 | Y1: =E1 -> 1 | AE1: =E1 -> 1
D2: Walls and Colums | E2: 0 | F2: =$C$6*E2 -> 0 | X2: =E2 -> 0 | Y2: =E2 -> 0 | AE2: =E2 -> 0
A3: PR# No: | C3: 70027046 | D3: Scaffolding | E3: 0 | F3: =$C$6*E3 -> 0 | X3: =E3 -> 0 | Y3: =E3 -> 0 | AE3: =E3 -> 0
A4: PR# Date: | C4: 46112 | D4: Safety | E4: 0 | F4: =$C$6*E4 -> 0 | K4: 1175 | M4: 1177 | N4: 1178 | T4: 1185 | X4: =E4 -> 0 | Y4: =E4 -> 0 | AB4: Return Qty | AE4: =E4 -> 0
A5: PR# For: | D5: Recived/Transfer Date: | F5: 46118 | G5: 46148 | H5: 46193 | I5: 46193 | J5: 46233 | K5: 46253 | L5: 46254 | M5: 46258 | N5: 46258 | O5: 46259 | P5: 46259 | Q5: 46260 | R5: 46266 | S5: 46266 | T5: 46267 | U5: 46287 | V5: 46287
A6: Area: | D6: Store Voucher No: | F6: 1167 | G6: 6299 | H6: 1173 | I6: 1172 | J6: 452 | L6: 1176
F7: Zone.G 400K | G7: Bab Misr | H7: 3407 | I7: 3406 | K7: Al Ayat (185) | M7: SOUL.1 (626) | N7: SOUL.1 (627) | O7: Al Ayat (187) | P7: Al Ayat (188) | Q7: NC.WWTP (1363) | R7: Belbies (1003) | S7: NCWWTP (1364) | T7: Stem Cells (759) | U7: Belbies (1004) | V7: Belbies (1005)
A8: No | B8: ASSET CODE | C8: FULL SERIAL | D8: ITEMS NAME | E8: Req Qty | F8: PIONEERS | G8: PIONEERS | H8: PIONEERS | I8: PIONEERS | J8: PIONEERS | K8: PIONEERS | L8: PIONEERS | M8: PIONEERS | N8: PIONEERS | O8: PIONEERS | P8: PIONEERS | Q8: PIONEERS | R8: PIONEERS | S8: PIONEERS | T8: PIONEERS | U8: PIONEERS | V8: PIONEERS | X8: Send Qty | Y8: Remain Qty | Z8: Remarks | AE8: T.Return
A9: 1 | B9: ='Unit Prices'!B9 -> CK0021 | C9: ='Unit Prices'!C9 -> 14.80.02.19.06.05.00.000001 | D9: ='Unit Prices'!D9 -> cuplock Vertical 0.5M | X9: =SUM(F9:W9) -> 0 | Y9: =E9-X9 -> 0 | AE9: =SUM(AB9:AD9) -> 0
A10: 2 | B10: ='Unit Prices'!B10 -> CK0018 | C10: ='Unit Prices'!C10 -> 14.80.02.19.06.01.00.000001 | D10: ='Unit Prices'!D10 -> cuplock Vertical 1M | X10: =SUM(F10:W10) -> 0 | Y10: =E10-X10 -> 0 | AE10: =SUM(AB10:AD10) -> 0
A11: 3 | B11: ='Unit Prices'!B11 -> CK0022 | C11: ='Unit Prices'!C11 -> 14.80.02.19.06.13.00.000001 | D11: ='Unit Prices'!D11 -> cuplock Vertical 1.3M | X11: =SUM(F11:W11) -> 0 | Y11: =E11-X11 -> 0 | AE11: =SUM(AB11:AD11) -> 0
A12: 4 | B12: ='Unit Prices'!B12 -> CK0023 | C12: ='Unit Prices'!C12 -> 14.80.02.19.06.15.00.000001 | D12: ='Unit Prices'!D12 -> cuplock Vertical 1.5M | E12: =265+100 -> 365 | F12: 265 | K12: 4 | L12: 4 | U12: 100 | X12: =SUM(F12:W12) -> 373 | Y12: =E12-X12 -> -8 | AE12: =SUM(AB12:AD12) -> 0
A13: 5 | B13: ='Unit Prices'!B13 -> CK0024 | C13: ='Unit Prices'!C13 -> 14.80.02.19.06.18.00.000001 | D13: ='Unit Prices'!D13 -> cuplock Vertical 1.8M | X13: =SUM(F13:W13) -> 0 | Y13: =E13-X13 -> 0 | AE13: =SUM(AB13:AD13) -> 0
A14: 6 | B14: ='Unit Prices'!B14 -> CK0019 | C14: ='Unit Prices'!C14 -> 14.80.02.19.06.02.00.000001 | D14: ='Unit Prices'!D14 -> cuplock Vertical 2M | E14: =56+50 -> 106 | F14: 56 | O14: 20 | X14: =SUM(F14:W14) -> 76 | Y14: =E14-X14 -> 30 | AE14: =SUM(AB14:AD14) -> 0
A15: 7 | B15: ='Unit Prices'!B15 -> CK0025 | C15: ='Unit Prices'!C15 -> 14.80.02.19.06.23.00.000001 | D15: ='Unit Prices'!D15 -> cuplock Vertical 2.3M | X15: =SUM(F15:W15) -> 0 | Y15: =E15-X15 -> 0 | AE15: =SUM(AB15:AD15) -> 0
A16: 8 | B16: ='Unit Prices'!B16 -> CK0026 | C16: ='Unit Prices'!C16 -> 14.80.02.19.06.25.00.000001 | D16: ='Unit Prices'!D16 -> cuplock Vertical 2.5M | E16: 370 | M16: 4 | S16: 165 | X16: =SUM(F16:W16) -> 169 | Y16: =E16-X16 -> 201 | AE16: =SUM(AB16:AD16) -> 0
A17: 9 | B17: ='Unit Prices'!B17 -> CK0027 | C17: ='Unit Prices'!C17 -> 14.80.02.19.06.28.00.000001 | D17: ='Unit Prices'!D17 -> cuplock Vertical 2.8M | X17: =SUM(F17:W17) -> 0 | Y17: =E17-X17 -> 0 | AE17: =SUM(AB17:AD17) -> 0
A18: 10 | B18: ='Unit Prices'!B18 -> CK0020 | C18: ='Unit Prices'!C18 -> 14.80.02.19.06.03.00.000001 | D18: ='Unit Prices'!D18 -> cuplock Vertical 3M | E18: 3000 | F18: 43 | K18: 320 | L18: 135 | O18: 770 | S18: 238 | X18: =SUM(F18:W18) -> 1506 | Y18: =E18-X18 -> 1494 | AE18: =SUM(AB18:AD18) -> 0
A19: 11 | B19: ='Unit Prices'!B19 -> CL0001 | C19: ='Unit Prices'!C19 -> 14.80.50.24.01.00.00.000001 | D19: ='Unit Prices'!D19 -> cuplock Spigot | X19: =SUM(F19:W19) -> 0 | Y19: =E19-X19 -> 0 | AE19: =SUM(AB19:AD19) -> 0
A20: 12 | B20: ='Unit Prices'!B20 -> CK0006 | C20: ='Unit Prices'!C20 -> 14.80.02.19.04.04.00.000001 | D20: ='Unit Prices'!D20 -> cuplock Ledger 0.4M | X20: =SUM(F20:W20) -> 0 | Y20: =E20-X20 -> 0 | AE20: =SUM(AB20:AD20) -> 0
A21: 13 | B21: ='Unit Prices'!B21 -> CK0007 | C21: ='Unit Prices'!C21 -> 14.80.02.19.04.06.00.000001 | D21: ='Unit Prices'!D21 -> cuplock Ledger 0.6M | E21: 157 | X21: =SUM(F21:W21) -> 0 | Y21: =E21-X21 -> 157 | AE21: =SUM(AB21:AD21) -> 0
A22: 14 | B22: ='Unit Prices'!B22 -> CK0028 | C22: ='Unit Prices'!C22 -> 14.80.02.19.04.08.00.000001 | D22: ='Unit Prices'!D22 -> cuplock Ledger 0.80 M | X22: =SUM(F22:W22) -> 0 | Y22: =E22-X22 -> 0 | AE22: =SUM(AB22:AD22) -> 0
A23: 15 | B23: ='Unit Prices'!B23 -> CK0008 | C23: ='Unit Prices'!C23 -> 14.80.02.19.04.09.00.000001 | D23: ='Unit Prices'!D23 -> cuplock Ledger 0.9M | E23: =2575+500 -> 3075 | H23: 849 | I23: 1165 | K23: 7 | L23: 3 | M23: 196 | N23: 10 | O23: 20 | R23: 400 | S23: 407 | V23: 220 | X23: =SUM(F23:W23) -> 3277 | Y23: =E23-X23 -> -202 | AE23: =SUM(AB23:AD23) -> 0
A24: 16 | B24: ='Unit Prices'!B24 -> CK0004 | C24: ='Unit Prices'!C24 -> 14.80.02.19.04.01.00.000001 | D24: ='Unit Prices'!D24 -> cuplock Ledger 1M | E24: 2014 | T24: 200 | X24: =SUM(F24:W24) -> 200 | Y24: =E24-X24 -> 1814 | AE24: =SUM(AB24:AD24) -> 0
A25: 17 | B25: ='Unit Prices'!B25 -> CK0010 | C25: ='Unit Prices'!C25 -> 14.80.02.19.04.12.00.000001 | D25: ='Unit Prices'!D25 -> cuplock Ledger 1.2M | E25: =6451 -> 6451 | K25: 8 | L25: 554 | O25: 820 | R25: 504 | S25: 1004 | U25: 8 | X25: =SUM(F25:W25) -> 2898 | Y25: =E25-X25 -> 3553 | AE25: =SUM(AB25:AD25) -> 0
A26: 18 | B26: ='Unit Prices'!B26 -> CK0009 | C26: ='Unit Prices'!C26 -> 14.80.02.19.04.11.00.000001 | D26: ='Unit Prices'!D26 -> cuplock Ledger 1.25M | X26: =SUM(F26:W26) -> 0 | Y26: =E26-X26 -> 0 | AE26: =SUM(AB26:AD26) -> 0
A27: 19 | B27: ='Unit Prices'!B27 -> CK0011 | C27: ='Unit Prices'!C27 -> 14.80.02.19.04.13.00.000001 | D27: ='Unit Prices'!D27 -> cuplock Ledger 1.3M | X27: =SUM(F27:W27) -> 0 | Y27: =E27-X27 -> 0 | AE27: =SUM(AB27:AD27) -> 0
A28: 20 | B28: ='Unit Prices'!B28 -> CK0012 | C28: ='Unit Prices'!C28 -> 14.80.02.19.04.15.00.000001 | D28: ='Unit Prices'!D28 -> cuplock Ledger 1.5M | E28: =10+500 -> 510 | F28: 2 | S28: 385 | X28: =SUM(F28:W28) -> 387 | Y28: =E28-X28 -> 123 | AE28: =SUM(AB28:AD28) -> 0
A29: 21 | B29: ='Unit Prices'!B29 -> CK0013 | C29: ='Unit Prices'!C29 -> 14.80.02.19.04.16.00.000001 | D29: ='Unit Prices'!D29 -> cuplock Ledger 1.6M | E29: =6000 -> 6000 | P29: 3000 | R29: 500 | X29: =SUM(F29:W29) -> 3500 | Y29: =E29-X29 -> 2500 | AE29: =SUM(AB29:AD29) -> 0
A30: 22 | B30: ='Unit Prices'!B30 -> CK0014 | C30: ='Unit Prices'!C30 -> 14.80.02.19.04.18.00.000001 | D30: ='Unit Prices'!D30 -> cuplock Ledger 1.8M | E30: 200 | M30: 80 | X30: =SUM(F30:W30) -> 80 | Y30: =E30-X30 -> 120 | AE30: =SUM(AB30:AD30) -> 0
A31: 23 | B31: ='Unit Prices'!B31 -> CK0015 | C31: ='Unit Prices'!C31 -> 14.80.02.19.04.21.00.000001 | D31: ='Unit Prices'!D31 -> cuplock Ledger 2.1M | X31: =SUM(F31:W31) -> 0 | Y31: =E31-X31 -> 0 | AE31: =SUM(AB31:AD31) -> 0
A32: 24 | B32: ='Unit Prices'!B32 -> CK0016 | C32: ='Unit Prices'!C32 -> 14.80.02.19.04.24.00.000001 | D32: ='Unit Prices'!D32 -> cuplock Ledger 2.40M | X32: =SUM(F32:W32) -> 0 | Y32: =E32-X32 -> 0 | AE32: =SUM(AB32:AD32) -> 0
A33: 25 | B33: ='Unit Prices'!B33 -> CK0017 | C33: ='Unit Prices'!C33 -> 14.80.02.19.04.25.00.000001 | D33: ='Unit Prices'!D33 -> cuplock Ledger 2.5M | X33: =SUM(F33:W33) -> 0 | Y33: =E33-X33 -> 0 | AE33: =SUM(AB33:AD33) -> 0
A34: 26 | B34: ='Unit Prices'!B34 -> CK0005 | C34: ='Unit Prices'!C34 -> 14.80.02.19.04.03.00.000001 | D34: ='Unit Prices'!D34 -> cuplock Ledger 3M | X34: =SUM(F34:W34) -> 0 | Y34: =E34-X34 -> 0 | AE34: =SUM(AB34:AD34) -> 0
A35: 27 | B35: ='Unit Prices'!B35 -> CK0001 | C35: ='Unit Prices'!C35 -> 14.80.02.19.01.00.00.000001 | D35: ='Unit Prices'!D35 -> cuplock BEAM BRACKET | X35: =SUM(F35:W35) -> 0 | Y35: =E35-X35 -> 0 | AE35: =SUM(AB35:AD35) -> 0
A36: 28 | B36: ='Unit Prices'!B36 -> CK0002 | C36: ='Unit Prices'!C36 -> 14.80.02.19.02.01.00.000001 | D36: ='Unit Prices'!D36 -> cuplock Cantilever Single | X36: =SUM(F36:W36) -> 0 | Y36: =E36-X36 -> 0 | AE36: =SUM(AB36:AD36) -> 0
A37: 29 | B37: ='Unit Prices'!B37 -> CK0003 | C37: ='Unit Prices'!C37 -> 14.80.02.19.02.02.00.000001 | D37: ='Unit Prices'!D37 -> cuplock Cantilever double | X37: =SUM(F37:W37) -> 0 | Y37: =E37-X37 -> 0 | AE37: =SUM(AB37:AD37) -> 0
A38: 30 | B38: ='Unit Prices'!B38 -> CK0029 | C38: ='Unit Prices'!C38 -> 14.80.02.19.08.36.00.000001 | D38: ='Unit Prices'!D38 -> Acrow Unit Beam 3.60 m | X38: =SUM(F38:W38) -> 0 | Y38: =E38-X38 -> 0 | AE38: =SUM(AB38:AD38) -> 0
A39: 31 | B39: ='Unit Prices'!B39 -> CK0030 | C39: ='Unit Prices'!C39 -> 14.80.02.19.08.27.00.000001 | D39: ='Unit Prices'!D39 -> Acrow Unit Beam 2.70 m | X39: =SUM(F39:W39) -> 0 | Y39: =E39-X39 -> 0 | AE39: =SUM(AB39:AD39) -> 0
A40: 32 | B40: ='Unit Prices'!B40 -> CK0031 | C40: ='Unit Prices'!C40 -> 14.80.02.19.08.24.00.000001 | D40: ='Unit Prices'!D40 -> Acrow Unit Beam 2.40 m | X40: =SUM(F40:W40) -> 0 | Y40: =E40-X40 -> 0 | AE40: =SUM(AB40:AD40) -> 0
...

Sheet 9400016451 VIDAFORM
A1: Project Name: | D1: Slab | E1: 1 | F1: =$C$6*E1 -> 0 | J1: =E1 -> 1 | K1: =E1 -> 1 | Q1: =E1 -> 1
D2: Walls and Colums | E2: 0 | F2: =$C$6*E2 -> 0 | J2: =E2 -> 0 | K2: =E2 -> 0 | Q2: =E2 -> 0
A3: PR# No: | C3: 70027046 | D3: Scaffolding | E3: 0 | F3: =$C$6*E3 -> 0 | J3: =E3 -> 0 | K3: =E3 -> 0 | Q3: =E3 -> 0
A4: PR# Date: | C4: 46159 | D4: Safety | E4: 0 | F4: =$C$6*E4 -> 0 | J4: =E4 -> 0 | K4: =E4 -> 0 | N4: Return Qty | Q4: =E4 -> 0
A5: PR# For: | D5: Recived/Transfer Date: | F5: 46161 | G5: 46179 | H5: 46263
A6: Area: | D6: Store Voucher No:
F7: 2 | G7: 9 | H7: 65
A8: No | B8: ASSET CODE | C8: FULL SERIAL | D8: ITEMS NAME | E8: Req Qty | F8: Vidaform | G8: Vidaform | H8: Vidaform | J8: Send Qty | K8: Remain Qty | L8: Remarks | Q8: T.Return
A9: 1 | B9: ='Unit Prices'!B9 -> CK0021 | C9: ='Unit Prices'!C9 -> 14.80.02.19.06.05.00.000001 | D9: ='Unit Prices'!D9 -> cuplock Vertical 0.5M | J9: =SUM(F9:I9) -> 0 | K9: =E9-J9 -> 0 | Q9: =SUM(N9:P9) -> 0
A10: 2 | B10: ='Unit Prices'!B10 -> CK0018 | C10: ='Unit Prices'!C10 -> 14.80.02.19.06.01.00.000001 | D10: ='Unit Prices'!D10 -> cuplock Vertical 1M | J10: =SUM(F10:I10) -> 0 | K10: =E10-J10 -> 0 | Q10: =SUM(N10:P10) -> 0
A11: 3 | B11: ='Unit Prices'!B11 -> CK0022 | C11: ='Unit Prices'!C11 -> 14.80.02.19.06.13.00.000001 | D11: ='Unit Prices'!D11 -> cuplock Vertical 1.3M | J11: =SUM(F11:I11) -> 0 | K11: =E11-J11 -> 0 | Q11: =SUM(N11:P11) -> 0
A12: 4 | B12: ='Unit Prices'!B12 -> CK0023 | C12: ='Unit Prices'!C12 -> 14.80.02.19.06.15.00.000001 | D12: ='Unit Prices'!D12 -> cuplock Vertical 1.5M | J12: =SUM(F12:I12) -> 0 | K12: =E12-J12 -> 0 | Q12: =SUM(N12:P12) -> 0
A13: 5 | B13: ='Unit Prices'!B13 -> CK0024 | C13: ='Unit Prices'!C13 -> 14.80.02.19.06.18.00.000001 | D13: ='Unit Prices'!D13 -> cuplock Vertical 1.8M | J13: =SUM(F13:I13) -> 0 | K13: =E13-J13 -> 0 | Q13: =SUM(N13:P13) -> 0
A14: 6 | B14: ='Unit Prices'!B14 -> CK0019 | C14: ='Unit Prices'!C14 -> 14.80.02.19.06.02.00.000001 | D14: ='Unit Prices'!D14 -> cuplock Vertical 2M | J14: =SUM(F14:I14) -> 0 | K14: =E14-J14 -> 0 | Q14: =SUM(N14:P14) -> 0
A15: 7 | B15: ='Unit Prices'!B15 -> CK0025 | C15: ='Unit Prices'!C15 -> 14.80.02.19.06.23.00.000001 | D15: ='Unit Prices'!D15 -> cuplock Vertical 2.3M | J15: =SUM(F15:I15) -> 0 | K15: =E15-J15 -> 0 | Q15: =SUM(N15:P15) -> 0
A16: 8 | B16: ='Unit Prices'!B16 -> CK0026 | C16: ='Unit Prices'!C16 -> 14.80.02.19.06.25.00.000001 | D16: ='Unit Prices'!D16 -> cuplock Vertical 2.5M | J16: =SUM(F16:I16) -> 0 | K16: =E16-J16 -> 0 | Q16: =SUM(N16:P16) -> 0
A17: 9 | B17: ='Unit Prices'!B17 -> CK0027 | C17: ='Unit Prices'!C17 -> 14.80.02.19.06.28.00.000001 | D17: ='Unit Prices'!D17 -> cuplock Vertical 2.8M | J17: =SUM(F17:I17) -> 0 | K17: =E17-J17 -> 0 | Q17: =SUM(N17:P17) -> 0
A18: 10 | B18: ='Unit Prices'!B18 -> CK0020 | C18: ='Unit Prices'!C18 -> 14.80.02.19.06.03.00.000001 | D18: ='Unit Prices'!D18 -> cuplock Vertical 3M | J18: =SUM(F18:I18) -> 0 | K18: =E18-J18 -> 0 | Q18: =SUM(N18:P18) -> 0
A19: 11 | B19: ='Unit Prices'!B19 -> CL0001 | C19: ='Unit Prices'!C19 -> 14.80.50.24.01.00.00.000001 | D19: ='Unit Prices'!D19 -> cuplock Spigot | J19: =SUM(F19:I19) -> 0 | K19: =E19-J19 -> 0 | Q19: =SUM(N19:P19) -> 0
A20: 12 | B20: ='Unit Prices'!B20 -> CK0006 | C20: ='Unit Prices'!C20 -> 14.80.02.19.04.04.00.000001 | D20: ='Unit Prices'!D20 -> cuplock Ledger 0.4M | J20: =SUM(F20:I20) -> 0 | K20: =E20-J20 -> 0 | Q20: =SUM(N20:P20) -> 0
... A22: 14 | B22: ='Unit Prices'!B22 -> CK0028 | C22: ='Unit Prices'!C22 -> 14.80.02.19.04.08.00.000001 | D22: ='Unit Prices'!D22 -> cuplock Ledger 0.80 M | J22: =SUM(F22:I22) -> 0 | K22: =E22-J22 -> 0 | Q22: =SUM(N22:P22) -> 0
A23: 15 | B23: ='Unit Prices'!B23 -> CK0008 | C23: ='Unit Prices'!C23 -> 14.80.02.19.04.09.00.000001 | D23: ='Unit Prices'!D23 -> cuplock Ledger 0.9M | E23: =1850+500 -> 2350 | F23: 1350 | G23: 500 | H23: 500 | J23: =SUM(F23:I23) -> 2350 | K23: =E23-J23 -> 0 | Q23: =SUM(N23:P23) -> 0
A24: 16 | B24: ='Unit Prices'!B24 -> CK0004 | C24: ='Unit Prices'!C24 -> 14.80.02.19.04.01.00.000001 | D24: ='Unit Prices'!D24 -> cuplock Ledger 1M | J24: =SUM(F24:I24) -> 0 | K24: =E24-J24 -> 0 | Q24: =SUM(N24:P24) -> 0
A25: 17 | B25: ='Unit Prices'!B25 -> CK0010 | C25: ='Unit Prices'!C25 -> 14.80.02.19.04.12.00.000001 | D25: ='Unit Prices'!D25 -> cuplock Ledger 1.2M | E25: =6000+1300 -> 7300 | F25: 4700 | G25: 1300 | H25: 1300 | J25: =SUM(F25:I25) -> 7300 | K25: =E25-J25 -> 0 | Q25: =SUM(N25:P25) -> 0
A26: 18 | B26: ='Unit Prices'!B26 -> CK0009 | C26: ='Unit Prices'!C26 -> 14.80.02.19.04.11.00.000001 | D26: ='Unit Prices'!D26 -> cuplock Ledger 1.25M | J26: =SUM(F26:I26) -> 0 | K26: =E26-J26 -> 0 | Q26: =SUM(N26:P26) -> 0
A27: 19 | B27: ='Unit Prices'!B27 -> CK0011 | C27: ='Unit Prices'!C27 -> 14.80.02.19.04.13.00.000001 | D27: ='Unit Prices'!D27 -> cuplock Ledger 1.3M | J27: =SUM(F27:I27) -> 0 | K27: =E27-J27 -> 0 | Q27: =SUM(N27:P27) -> 0
A28: 20 | B28: ='Unit Prices'!B28 -> CK0012 | C28: ='Unit Prices'!C28 -> 14.80.02.19.04.15.00.000001 | D28: ='Unit Prices'!D28 -> cuplock Ledger 1.5M | J28: =SUM(F28:I28) -> 0 | K28: =E28-J28 -> 0 | Q28: =SUM(N28:P28) -> 0
A29: 21 | B29: ='Unit Prices'!B29 -> CK0013 | C29: ='Unit Prices'!C29 -> 14.80.02.19.04.16.00.000001 | D29: ='Unit Prices'!D29 -> cuplock Ledger 1.6M | J29: =SUM(F29:I29) -> 0 | K29: =E29-J29 -> 0 | Q29: =SUM(N29:P29) -> 0
A30: 22 | B30: ='Unit Prices'!B30 -> CK0014 | C30: ='Unit Prices'!C30 -> 14.80.02.19.04.18.00.000001 | D30: ='Unit Prices'!D30 -> cuplock Ledger 1.8M | J30: =SUM(F30:I30) -> 0 | K30: =E30-J30 -> 0 | Q30: =SUM(N30:P30) -> 0
A31: 23 | B31: ='Unit Prices'!B31 -> CK0015 | C31: ='Unit Prices'!C31 -> 14.80.02.19.04.21.00.000001 | D31: ='Unit Prices'!D31 -> cuplock Ledger 2.1M | J31: =SUM(F31:I31) -> 0 | K31: =E31-J31 -> 0 | Q31: =SUM(N31:P31) -> 0
A32: 24 | B32: ='Unit Prices'!B32 -> CK0016 | C32: ='Unit Prices'!C32 -> 14.80.02.19.04.24.00.000001 | D32: ='Unit Prices'!D32 -> cuplock Ledger 2.40M | J32: =SUM(F32:I32) -> 0 | K32: =E32-J32 -> 0 | Q32: =SUM(N32:P32) -> 0
A33: 25 | B33: ='Unit Prices'!B33 -> CK0017 | C33: ='Unit Prices'!C33 -> 14.80.02.19.04.25.00.000001 | D33: ='Unit Prices'!D33 -> cuplock Ledger 2.5M | J33: =SUM(F33:I33) -> 0 | K33: =E33-J33 -> 0 | Q33: =SUM(N33:P33) -> 0
A34: 26 | B34: ='Unit Prices'!B34 -> CK0005 | C34: ='Unit Prices'!C34 -> 14.80.02.19.04.03.00.000001 | D34: ='Unit Prices'!D34 -> cuplock Ledger 3M | J34: =SUM(F34:I34) -> 0 | K34: =E34-J34 -> 0 | Q34: =SUM(N34:P34) -> 0
A35: 27 | B35: ='Unit Prices'!B35 -> CK0001 | C35: ='Unit Prices'!C35 -> 14.80.02.19.01.00.00.000001 | D35: ='Unit Prices'!D35 -> cuplock BEAM BRACKET | J35: =SUM(F35:I35) -> 0 | K35: =E35-J35 -> 0 | Q35: =SUM(N35:P35) -> 0
A36: 28 | B36: ='Unit Prices'!B36 -> CK0002 | C36: ='Unit Prices'!C36 -> 14.80.02.19.02.01.00.000001 | D36: ='Unit Prices'!D36 -> cuplock Cantilever Single | J36: =SUM(F36:I36) -> 0 | K36: =E36-J36 -> 0 | Q36: =SUM(N36:P36) -> 0
A37: 29 | B37: ='Unit Prices'!B37 -> CK0003 | C37: ='Unit Prices'!C37 -> 14.80.02.19.02.02.00.000001 | D37: ='Unit Prices'!D37 -> cuplock Cantilever double | J37: =SUM(F37:I37) -> 0 | K37: =E37-J37 -> 0 | Q37: =SUM(N37:P37) -> 0
... A87: 79 | B87: ='Unit Prices'!B87 -> SF0008 | C87: ='Unit Prices'!C87 -> 14.80.02.23.04.30.00.000001 | D87: ='Unit Prices'!D87 -> scaffold Steel plank 3M | J87: =SUM(F87:I87) -> 0 | K87: =E87-J87 -> 0 | Q87: =SUM(N87:P87) -> 0
A88: 80 | B88: ='Unit Prices'!B88 -> BJ0001 | C88: ='Unit Prices'!C88 -> 14.80.02.02.00.00.00.000001 | D88: ='Unit Prices'!D88 -> BASE-Jack | E88: =2728+600 -> 3328 | F88: 2128 | G88: 600 | H88: 600 | J88: =SUM(F88:I88) -> 3328 | K88: =E88-J88 -> 0 | Q88: =SUM(N88:P88) -> 0
A89: 81 | B89: ='Unit Prices'!B89 -> BP0001 | C89: ='Unit Prices'!C89 -> 14.80.02.03.00.00.00.000001 | D89: ='Unit Prices'!D89 -> BASE-Plain | J89: =SUM(F89:I89) -> 0 | K89: =E89-J89 -> 0 | Q89: =SUM(N89:P89) -> 0
A90: 82 | B90: ='Unit Prices'!B90 -> UH0002 | C90: ='Unit Prices'!C90 -> 14.80.02.18.01.00.00.000001 | D90: ='Unit Prices'!D90 -> U-Head with jack | E90: 660 | F90: 310 | G90: 350 | J90: =SUM(F90:I90) -> 660 | K90: =E90-J90 -> 0 | Q90: =SUM(N90:P90) -> 0
...

Sheet PO 94000171374 MASTER
A1: Project Name: | D1: Slab | E1: 0 | F1: =$C$6*E1 -> 0 | I1: =E1 -> 0 | J1: =E1 -> 0 | P1: =I1 -> 0
D2: Walls and Colums | E2: 0 | F2: =$C$6*E2 -> 0 | I2: =E2 -> 0 | J2: =E2 -> 0 | P2: =I2 -> 0
A3: PR# No: | D3: Scaffolding | E3: 1 | F3: =$C$6*E3 -> 0 | I3: =E3 -> 1 | J3: =E3 -> 1 | P3: =I3 -> 1
A4: PR# Date: | D4: Safety | E4: 0 | F4: =$C$6*E4 -> 0 | I4: =E4 -> 0 | J4: =E4 -> 0 | M4: Return Qty | P4: =I4 -> 0
A5: PR# For: | D5: Recived/Transfer Date: | F5: 46284
A6: Area: | D6: Store Voucher No: | F6: 54
F7: 6910
A8: No | B8: ASSET CODE | C8: FULL SERIAL | D8: ITEMS NAME | E8: Req Qty | F8: MASTER | I8: Send Qty | J8: Remain Qty | K8: Remarks | P8: T.Return
A9: 1 | B9: ='Unit Prices'!B9 -> CK0021 | C9: ='Unit Prices'!C9 -> 14.80.02.19.06.05.00.000001 | D9: ='Unit Prices'!D9 -> cuplock Vertical 0.5M | E9: 300 | I9: =SUM(F9:H9) -> 0 | J9: =E9-I9 -> 300 | P9: =SUM(M9:O9) -> 0
A10: 2 | B10: ='Unit Prices'!B10 -> CK0018 | C10: ='Unit Prices'!C10 -> 14.80.02.19.06.01.00.000001 | D10: ='Unit Prices'!D10 -> cuplock Vertical 1M | E10: 900 | I10: =SUM(F10:H10) -> 0 | J10: =E10-I10 -> 900 | P10: =SUM(M10:O10) -> 0
A11: 3 | B11: ='Unit Prices'!B11 -> CK0022 | C11: ='Unit Prices'!C11 -> 14.80.02.19.06.13.00.000001 | D11: ='Unit Prices'!D11 -> cuplock Vertical 1.3M | I11: =SUM(F11:H11) -> 0 | J11: =E11-I11 -> 0 | P11: =SUM(M11:O11) -> 0
A12: 4 | B12: ='Unit Prices'!B12 -> CK0023 | C12: ='Unit Prices'!C12 -> 14.80.02.19.06.15.00.000001 | D12: ='Unit Prices'!D12 -> cuplock Vertical 1.5M | E12: 500 | I12: =SUM(F12:H12) -> 0 | J12: =E12-I12 -> 500 | P12: =SUM(M12:O12) -> 0
A13: 5 | B13: ='Unit Prices'!B13 -> CK0024 | C13: ='Unit Prices'!C13 -> 14.80.02.19.06.18.00.000001 | D13: ='Unit Prices'!D13 -> cuplock Vertical 1.8M | I13: =SUM(F13:H13) -> 0 | J13: =E13-I13 -> 0 | P13: =SUM(M13:O13) -> 0
A14: 6 | B14: ='Unit Prices'!B14 -> CK0019 | C14: ='Unit Prices'!C14 -> 14.80.02.19.06.02.00.000001 | D14: ='Unit Prices'!D14 -> cuplock Vertical 2M | E14: 800 | I14: =SUM(F14:H14) -> 0 | J14: =E14-I14 -> 800 | P14: =SUM(M14:O14) -> 0
A15: 7 | B15: ='Unit Prices'!B15 -> CK0025 | C15: ='Unit Prices'!C15 -> 14.80.02.19.06.23.00.000001 | D15: ='Unit Prices'!D15 -> cuplock Vertical 2.3M | I15: =SUM(F15:H15) -> 0 | J15: =E15-I15 -> 0 | P15: =SUM(M15:O15) -> 0
A16: 8 | B16: ='Unit Prices'!B16 -> CK0026 | C16: ='Unit Prices'!C16 -> 14.80.02.19.06.25.00.000001 | D16: ='Unit Prices'!D16 -> cuplock Vertical 2.5M | I16: =SUM(F16:H16) -> 0 | J16: =E16-I16 -> 0 | P16: =SUM(M16:O16) -> 0
A17: 9 | B17: ='Unit Prices'!B17 -> CK0027 | C17: ='Unit Prices'!C17 -> 14.80.02.19.06.28.00.000001 | D17: ='Unit Prices'!D17 -> cuplock Vertical 2.8M | I17: =SUM(F17:H17) -> 0 | J17: =E17-I17 -> 0 | P17: =SUM(M17:O17) -> 0
A18: 10 | B18: ='Unit Prices'!B18 -> CK0020 | C18: ='Unit Prices'!C18 -> 14.80.02.19.06.03.00.000001 | D18: ='Unit Prices'!D18 -> cuplock Vertical 3M | I18: =SUM(F18:H18) -> 0 | J18: =E18-I18 -> 0 | P18: =SUM(M18:O18) -> 0
A19: 11 | B19: ='Unit Prices'!B19 -> CL0001 | C19: ='Unit Prices'!C19 -> 14.80.50.24.01.00.00.000001 | D19: ='Unit Prices'!D19 -> cuplock Spigot | I19: =SUM(F19:H19) -> 0 | J19: =E19-I19 -> 0 | P19: =SUM(M19:O19) -> 0
A20: 12 | B20: ='Unit Prices'!B20 -> CK0006 | C20: ='Unit Prices'!C20 -> 14.80.02.19.04.04.00.000001 | D20: ='Unit Prices'!D20 -> cuplock Ledger 0.4M | I20: =SUM(F20:H20) -> 0 | J20: =E20-I20 -> 0 | P20: =SUM(M20:O20) -> 0
A21: 13 | B21: ='Unit Prices'!B21 -> CK0007 | C21: ='Unit Prices'!C21 -> 14.80.02.19.04.06.00.000001 | D21: ='Unit Prices'!D21 -> cuplock Ledger 0.6M | I21: =SUM(F21:H21) -> 0 | J21: =E21-I21 -> 0 | P21: =SUM(M21:O21) -> 0
A22: 14 | B22: ='Unit Prices'!B22 -> CK0028 | C22: ='Unit Prices'!C22 -> 14.80.02.19.04.08.00.000001 | D22: ='Unit Prices'!D22 -> cuplock Ledger 0.80 M | I22: =SUM(F22:H22) -> 0 | J22: =E22-I22 -> 0 | P22: =SUM(M22:O22) -> 0
A23: 15 | B23: ='Unit Prices'!B23 -> CK0008 | C23: ='Unit Prices'!C23 -> 14.80.02.19.04.09.00.000001 | D23: ='Unit Prices'!D23 -> cuplock Ledger 0.9M | E23: 1000 | I23: =SUM(F23:H23) -> 0 | J23: =E23-I23 -> 1000 | P23: =SUM(M23:O23) -> 0
A24: 16 | B24: ='Unit Prices'!B24 -> CK0004 | C24: ='Unit Prices'!C24 -> 14.80.02.19.04.01.00.000001 | D24: ='Unit Prices'!D24 -> cuplock Ledger 1M | E24: 1600 | I24: =SUM(F24:H24) -> 0 | J24: =E24-I24 -> 1600 | P24: =SUM(M24:O24) -> 0
A25: 17 | B25: ='Unit Prices'!B25 -> CK0010 | C25: ='Unit Prices'!C25 -> 14.80.02.19.04.12.00.000001 | D25: ='Unit Prices'!D25 -> cuplock Ledger 1.2M | I25: =SUM(F25:H25) -> 0 | J25: =E25-I25 -> 0 | P25: =SUM(M25:O25) -> 0
A26: 18 | B26: ='Unit Prices'!B26 -> CK0009 | C26: ='Unit Prices'!C26 -> 14.80.02.19.04.11.00.000001 | D26: ='Unit Prices'!D26 -> cuplock Ledger 1.25M | E26: 700 | I26: =SUM(F26:H26) -> 0 | J26: =E26-I26 -> 700 | P26: =SUM(M26:O26) -> 0
A27: 19 | B27: ='Unit Prices'!B27 -> CK0011 | C27: ='Unit Prices'!C27 -> 14.80.02.19.04.13.00.000001 | D27: ='Unit Prices'!D27 -> cuplock Ledger 1.3M | E27: 1010 | I27: =SUM(F27:H27) -> 0 | J27: =E27-I27 -> 1010 | P27: =SUM(M27:O27) -> 0
A28: 20 | B28: ='Unit Prices'!B28 -> CK0012 | C28: ='Unit Prices'!C28 -> 14.80.02.19.04.15.00.000001 | D28: ='Unit Prices'!D28 -> cuplock Ledger 1.5M | I28: =SUM(F28:H28) -> 0 | J28: =E28-I28 -> 0 | P28: =SUM(M28:O28) -> 0
A29: 21 | B29: ='Unit Prices'!B29 -> CK0013 | C29: ='Unit Prices'!C29 -> 14.80.02.19.04.16.00.000001 | D29: ='Unit Prices'!D29 -> cuplock Ledger 1.6M | I29: =SUM(F29:H29) -> 0 | J29: =E29-I29 -> 0 | P29: =SUM(M29:O29) -> 0
A30: 22 | B30: ='Unit Prices'!B30 -> CK0014 | C30: ='Unit Prices'!C30 -> 14.80.02.19.04.18.00.000001 | D30: ='Unit Prices'!D30 -> cuplock Ledger 1.8M | I30: =SUM(F30:H30) -> 0 | J30: =E30-I30 -> 0 | P30: =SUM(M30:O30) -> 0
A31: 23 | B31: ='Unit Prices'!B31 -> CK0015 | C31: ='Unit Prices'!C31 -> 14.80.02.19.04.21.00.000001 | D31: ='Unit Prices'!D31 -> cuplock Ledger 2.1M | I31: =SUM(F31:H31) -> 0 | J31: =E31-I31 -> 0 | P31: =SUM(M31:O31) -> 0
A32: 24 | B32: ='Unit Prices'!B32 -> CK0016 | C32: ='Unit Prices'!C32 -> 14.80.02.19.04.24.00.000001 | D32: ='Unit Prices'!D32 -> cuplock Ledger 2.40M | I32: =SUM(F32:H32) -> 0 | J32: =E32-I32 -> 0 | P32: =SUM(M32:O32) -> 0
A33: 25 | B33: ='Unit Prices'!B33 -> CK0017 | C33: ='Unit Prices'!C33 -> 14.80.02.19.04.25.00.000001 | D33: ='Unit Prices'!D33 -> cuplock Ledger 2.5M | I33: =SUM(F33:H33) -> 0 | J33: =E33-I33 -> 0 | P33: =SUM(M33:O33) -> 0
A34: 26 | B34: ='Unit Prices'!B34 -> CK0005 | C34: ='Unit Prices'!C34 -> 14.80.02.19.04.03.00.000001 | D34: ='Unit Prices'!D34 -> cuplock Ledger 3M | I34: =SUM(F34:H34) -> 0 | J34: =E34-I34 -> 0 | P34: =SUM(M34:O34) -> 0
A35: 27 | B35: ='Unit Prices'!B35 -> CK0001 | C35: ='Unit Prices'!C35 -> 14.80.02.19.01.00.00.000001 | D35: ='Unit Prices'!D35 -> cuplock BEAM BRACKET | I35: =SUM(F35:H35) -> 0 | J35: =E35-I35 -> 0 | P35: =SUM(M35:O35) -> 0
A36: 28 | B36: ='Unit Prices'!B36 -> CK0002 | C36: ='Unit Prices'!C36 -> 14.80.02.19.02.01.00.000001 | D36: ='Unit Prices'!D36 -> cuplock Cantilever Single | I36: =SUM(F36:H36) -> 0 | J36: =E36-I36 -> 0 | P36: =SUM(M36:O36) -> 0
A37: 29 | B37: ='Unit Prices'!B37 -> CK0003 | C37: ='Unit Prices'!C37 -> 14.80.02.19.02.02.00.000001 | D37: ='Unit Prices'!D37 -> cuplock Cantilever double | I37: =SUM(F37:H37) -> 0 | J37: =E37-I37 -> 0 | P37: =SUM(M37:O37) -> 0
A38: 30 | B38: ='Unit Prices'!B38 -> CK0029 | C38: ='Unit Prices'!C38 -> 14.80.02.19.08.36.00.000001 | D38: ='Unit Prices'!D38 -> Acrow Unit Beam 3.60 m | I38: =SUM(F38:H38) -> 0 | J38: =E38-I38 -> 0 | P38: =SUM(M38:O38) -> 0
A39: 31 | B39: ='Unit Prices'!B39 -> CK0030 | C39: ='Unit Prices'!C39 -> 14.80.02.19.08.27.00.000001 | D39: ='Unit Prices'!D39 -> Acrow Unit Beam 2.70 m | I39: =SUM(F39:H39) -> 0 | J39: =E39-I39 -> 0 | P39: =SUM(M39:O39) -> 0
... A94: 86 | B94: ='Unit Prices'!B94 -> FH0001 | C94: ='Unit Prices'!C94 -> 14.80.02.11.00.00.00.000001 | D94: ='Unit Prices'!D94 -> fork Head | I94: =SUM(F94:H94) -> 0 | J94: =E94-I94 -> 0 | P94: =SUM(M94:O94) -> 0
...

Sheet PR-0004
A1: Project Name: | D1: Slab | E1: 0 | F1: =$C$6*E1 -> 0 | I1: =E1 -> 0 | J1: =E1 -> 0 | P1: =I1 -> 0
D2: Walls and Colums | E2: 0 | F2: =$C$6*E2 -> 0 | I2: =E2 -> 0 | J2: =E2 -> 0 | P2: =I2 -> 0
A3: PR# No: | D3: Scaffolding | E3: 0 | F3: =$C$6*E3 -> 0 | I3: =E3 -> 0 | J3: =E3 -> 0 | P3: =I3 -> 0
A4: PR# Date: | D4: Safety | E4: 0 | F4: =$C$6*E4 -> 0 | I4: =E4 -> 0 | J4: =E4 -> 0 | M4: Return Qty | P4: =I4 -> 0
A5: PR# For: | D5: Recived/Transfer Date:
A6: Area: | D6: Store Voucher No:
A8: No | B8: ASSET CODE | C8: FULL SERIAL | D8: ITEMS NAME | E8: Req Qty | I8: Send Qty | J8: Remain Qty | K8: Remarks | P8: T.Return
A9: 1 | B9: ='Unit Prices'!B9 -> CK0021 | C9: ='Unit Prices'!C9 -> 14.80.02.19.06.05.00.000001 | D9: ='Unit Prices'!D9 -> cuplock Vertical 0.5M | I9: =SUM(F9:H9) -> 0 | J9: =E9-I9 -> 0 | P9: =SUM(M9:O9) -> 0
A10: 2 | B10: ='Unit Prices'!B10 -> CK0018 | C10: ='Unit Prices'!C10 -> 14.80.02.19.06.01.00.000001 | D10: ='Unit Prices'!D10 -> cuplock Vertical 1M | I10: =SUM(F10:H10) -> 0 | J10: =E10-I10 -> 0 | P10: =SUM(M10:O10) -> 0
A11: 3 | B11: ='Unit Prices'!B11 -> CK0022 | C11: ='Unit Prices'!C11 -> 14.80.02.19.06.13.00.000001 | D11: ='Unit Prices'!D11 -> cuplock Vertical 1.3M | I11: =SUM(F11:H11) -> 0 | J11: =E11-I11 -> 0 | P11: =SUM(M11:O11) -> 0
A12: 4 | B12: ='Unit Prices'!B12 -> CK0023 | C12: ='Unit Prices'!C12 -> 14.80.02.19.06.15.00.000001 | D12: ='Unit Prices'!D12 -> cuplock Vertical 1.5M | I12: =SUM(F12:H12) -> 0 | J12: =E12-I12 -> 0 | P12: =SUM(M12:O12) -> 0
A13: 5 | B13: ='Unit Prices'!B13 -> CK0024 | C13: ='Unit Prices'!C13 -> 14.80.02.19.06.18.00.000001 | D13: ='Unit Prices'!D13 -> cuplock Vertical 1.8M | I13: =SUM(F13:H13) -> 0 | J13: =E13-I13 -> 0 | P13: =SUM(M13:O13) -> 0
A14: 6 | B14: ='Unit Prices'!B14 -> CK0019 | C14: ='Unit Prices'!C14 -> 14.80.02.19.06.02.00.000001 | D14: ='Unit Prices'!D14 -> cuplock Vertical 2M | I14: =SUM(F14:H14) -> 0 | J14: =E14-I14 -> 0 | P14: =SUM(M14:O14) -> 0
A15: 7 | B15: ='Unit Prices'!B15 -> CK0025 | C15: ='Unit Prices'!C15 -> 14.80.02.19.06.23.00.000001 | D15: ='Unit Prices'!D15 -> cuplock Vertical 2.3M | I15: =SUM(F15:H15) -> 0 | J15: =E15-I15 -> 0 | P15: =SUM(M15:O15) -> 0
A16: 8 | B16: ='Unit Prices'!B16 -> CK0026 | C16: ='Unit Prices'!C16 -> 14.80.02.19.06.25.00.000001 | D16: ='Unit Prices'!D16 -> cuplock Vertical 2.5M | I16: =SUM(F16:H16) -> 0 | J16: =E16-I16 -> 0 | P16: =SUM(M16:O16) -> 0
A17: 9 | B17: ='Unit Prices'!B17 -> CK0027 | C17: ='Unit Prices'!C17 -> 14.80.02.19.06.28.00.000001 | D17: ='Unit Prices'!D17 -> cuplock Vertical 2.8M | I17: =SUM(F17:H17) -> 0 | J17: =E17-I17 -> 0 | P17: =SUM(M17:O17) -> 0
A18: 10 | B18: ='Unit Prices'!B18 -> CK0020 | C18: ='Unit Prices'!C18 -> 14.80.02.19.06.03.00.000001 | D18: ='Unit Prices'!D18 -> cuplock Vertical 3M | I18: =SUM(F18:H18) -> 0 | J18: =E18-I18 -> 0 | P18: =SUM(M18:O18) -> 0
A19: 11 | B19: ='Unit Prices'!B19 -> CL0001 | C19: ='Unit Prices'!C19 -> 14.80.50.24.01.00.00.000001 | D19: ='Unit Prices'!D19 -> cuplock Spigot | I19: =SUM(F19:H19) -> 0 | J19: =E19-I19 -> 0 | P19: =SUM(M19:O19) -> 0
A20: 12 | B20: ='Unit Prices'!B20 -> CK0006 | C20: ='Unit Prices'!C20 -> 14.80.02.19.04.04.00.000001 | D20: ='Unit Prices'!D20 -> cuplock Ledger 0.4M | I20: =SUM(F20:H20) -> 0 | J20: =E20-I20 -> 0 | P20: =SUM(M20:O20) -> 0
... A758: 750 | B758: ='Unit Prices'!B758 -> 0 | C758: ='Unit Prices'!C758 -> 0 | D758: ='Unit Prices'!D758 -> #N/A | I758: =SUM(F758:H758) -> 0 | J758: =E758-I758 -> 0 | P758: =SUM(M758:O758) -> 0

Sheet PR-0005
A1: Project Name: | D1: Slab | E1: 0 | F1: =$C$6*E1 -> 0 | I1: =E1 -> 0 | J1: =E1 -> 0 | P1: =I1 -> 0
D2: Walls and Colums | E2: 0 | F2: =$C$6*E2 -> 0 | I2: =E2 -> 0 | J2: =E2 -> 0 | P2: =I2 -> 0
A3: PR# No: | D3: Scaffolding | E3: 0 | F3: =$C$6*E3 -> 0 | I3: =E3 -> 0 | J3: =E3 -> 0 | P3: =I3 -> 0
A4: PR# Date: | D4: Safety | E4: 0 | F4: =$C$6*E4 -> 0 | I4: =E4 -> 0 | J4: =E4 -> 0 | M4: Return Qty | P4: =I4 -> 0
A5: PR# For: | D5: Recived/Transfer Date:
A6: Area: | D6: Store Voucher No:
A8: No | B8: ASSET CODE | C8: FULL SERIAL | D8: ITEMS NAME | E8: Req Qty | I8: Send Qty | J8: Remain Qty | K8: Remarks | P8: T.Return
A9: 1 | B9: ='Unit Prices'!B9 -> CK0021 | C9: ='Unit Prices'!C9 -> 14.80.02.19.06.05.00.000001 | D9: ='Unit Prices'!D9 -> cuplock Vertical 0.5M | I9: =SUM(F9:H9) -> 0 | J9: =E9-I9 -> 0 | P9: =SUM(M9:O9) -> 0
A10: 2 | B10: ='Unit Prices'!B10 -> CK0018 | C10: ='Unit Prices'!C10 -> 14.80.02.19.06.01.00.000001 | D10: ='Unit Prices'!D10 -> cuplock Vertical 1M | I10: =SUM(F10:H10) -> 0 | J10: =E10-I10 -> 0 | P10: =SUM(M10:O10) -> 0
A11: 3 | B11: ='Unit Prices'!B11 -> CK0022 | C11: ='Unit Prices'!C11 -> 14.80.02.19.06.13.00.000001 | D11: ='Unit Prices'!D11 -> cuplock Vertical 1.3M | I11: =SUM(F11:H11) -> 0 | J11: =E11-I11 -> 0 | P11: =SUM(M11:O11) -> 0
A12: 4 | B12: ='Unit Prices'!B12 -> CK0023 | C12: ='Unit Prices'!C12 -> 14.80.02.19.06.15.00.000001 | D12: ='Unit Prices'!D12 -> cuplock Vertical 1.5M | I12: =SUM(F12:H12) -> 0 | J12: =E12-I12 -> 0 | P12: =SUM(M12:O12) -> 0
A13: 5 | B13: ='Unit Prices'!B13 -> CK0024 | C13: ='Unit Prices'!C13 -> 14.80.02.19.06.18.00.000001 | D13: ='Unit Prices'!D13 -> cuplock Vertical 1.8M | I13: =SUM(F13:H13) -> 0 | J13: =E13-I13 -> 0 | P13: =SUM(M13:O13) -> 0
A14: 6 | B14: ='Unit Prices'!B14 -> CK0019 | C14: ='Unit Prices'!C14 -> 14.80.02.19.06.02.00.000001 | D14: ='Unit Prices'!D14 -> cuplock Vertical 2M | I14: =SUM(F14:H14) -> 0 | J14: =E14-I14 -> 0 | P14: =SUM(M14:O14) -> 0
A15: 7 | B15: ='Unit Prices'!B15 -> CK0025 | C15: ='Unit Prices'!C15 -> 14.80.02.19.06.23.00.000001 | D15: ='Unit Prices'!D15 -> cuplock Vertical 2.3M | I15: =SUM(F15:H15) -> 0 | J15: =E15-I15 -> 0 | P15: =SUM(M15:O15) -> 0
A16: 8 | B16: ='Unit Prices'!B16 -> CK0026 | C16: ='Unit Prices'!C16 -> 14.80.02.19.06.25.00.000001 | D16: ='Unit Prices'!D16 -> cuplock Vertical 2.5M | I16: =SUM(F16:H16) -> 0 | J16: =E16-I16 -> 0 | P16: =SUM(M16:O16) -> 0
A17: 9 | B17: ='Unit Prices'!B17 -> CK0027 | C17: ='Unit Prices'!C17 -> 14.80.02.19.06.28.00.000001 | D17: ='Unit Prices'!D17 -> cuplock Vertical 2.8M | I17: =SUM(F17:H17) -> 0 | J17: =E17-I17 -> 0 | P17: =SUM(M17:O17) -> 0
A18: 10 | B18: ='Unit Prices'!B18 -> CK0020 | C18: ='Unit Prices'!C18 -> 14.80.02.19.06.03.00.000001 | D18: ='Unit Prices'!D18 -> cuplock Vertical 3M | I18: =SUM(F18:H18) -> 0 | J18: =E18-I18 -> 0 | P18: =SUM(M18:O18) -> 0
A19: 11 | B19: ='Unit Prices'!B19 -> CL0001 | C19: ='Unit Prices'!C19 -> 14.80.50.24.01.00.00.000001 | D19: ='Unit Prices'!D19 -> cuplock Spigot | I19: =SUM(F19:H19) -> 0 | J19: =E19-I19 -> 0 | P19: =SUM(M19:O19) -> 0
A20: 12 | B20: ='Unit Prices'!B20 -> CK0006 | C20: ='Unit Prices'!C20 -> 14.80.02.19.04.04.00.000001 | D20: ='Unit Prices'!D20 -> cuplock Ledger 0.4M | I20: =SUM(F20:H20) -> 0 | J20: =E20-I20 -> 0 | P20: =SUM(M20:O20) -> 0
... A758: 750 | B758: ='Unit Prices'!B758 -> 0 | C758: ='Unit Prices'!C758 -> 0 | D758: ='Unit Prices'!D758 -> #N/A | I758: =SUM(F758:H758) -> 0 | J758: =E758-I758 -> 0 | P758: =SUM(M758:O758) -> 0

Sheet PR-0006
A1: Project Name: | D1: Slab | E1: 0 | F1: =$C$6*E1 -> 0 | I1: =E1 -> 0 | J1: =E1 -> 0 | P1: =I1 -> 0
D2: Walls and Colums | E2: 0 | F2: =$C$6*E2 -> 0 | I2: =E2 -> 0 | J2: =E2 -> 0 | P2: =I2 -> 0
A3: PR# No: | D3: Scaffolding | E3: 0 | F3: =$C$6*E3 -> 0 | I3: =E3 -> 0 | J3: =E3 -> 0 | P3: =I3 -> 0
A4: PR# Date: | D4: Safety | E4: 0 | F4: =$C$6*E4 -> 0 | I4: =E4 -> 0 | J4: =E4 -> 0 | M4: Return Qty | P4: =I4 -> 0
A5: PR# For: | D5: Recived/Transfer Date:
A6: Area: | D6: Store Voucher No:
A8: No | B8: ASSET CODE | C8: FULL SERIAL | D8: ITEMS NAME | E8: Req Qty | I8: Send Qty | J8: Remain Qty | K8: Remarks | P8: T.Return
A9: 1 | B9: ='Unit Prices'!B9 -> CK0021 | C9: ='Unit Prices'!C9 -> 14.80.02.19.06.05.00.000001 | D9: ='Unit Prices'!D9 -> cuplock Vertical 0.5M | I9: =SUM(F9:H9) -> 0 | J9: =E9-I9 -> 0 | P9: =SUM(M9:O9) -> 0
A10: 2 | B10: ='Unit Prices'!B10 -> CK0018 | C10: ='Unit Prices'!C10 -> 14.80.02.19.06.01.00.000001 | D10: ='Unit Prices'!D10 -> cuplock Vertical 1M | I10: =SUM(F10:H10) -> 0 | J10: =E10-I10 -> 0 | P10: =SUM(M10:O10) -> 0
A11: 3 | B11: ='Unit Prices'!B11 -> CK0022 | C11: ='Unit Prices'!C11 -> 14.80.02.19.06.13.00.000001 | D11: ='Unit Prices'!D11 -> cuplock Vertical 1.3M | I11: =SUM(F11:H11) -> 0 | J11: =E11-I11 -> 0 | P11: =SUM(M11:O11) -> 0
A12: 4 | B12: ='Unit Prices'!B12 -> CK0023 | C12: ='Unit Prices'!C12 -> 14.80.02.19.06.15.00.000001 | D12: ='Unit Prices'!D12 -> cuplock Vertical 1.5M | I12: =SUM(F12:H12) -> 0 | J12: =E12-I12 -> 0 | P12: =SUM(M12:O12) -> 0
A13: 5 | B13: ='Unit Prices'!B13 -> CK0024 | C13: ='Unit Prices'!C13 -> 14.80.02.19.06.18.00.000001 | D13: ='Unit Prices'!D13 -> cuplock Vertical 1.8M | I13: =SUM(F13:H13) -> 0 | J13: =E13-I13 -> 0 | P13: =SUM(M13:O13) -> 0
A14: 6 | B14: ='Unit Prices'!B14 -> CK0019 | C14: ='Unit Prices'!C14 -> 14.80.02.19.06.02.00.000001 | D14: ='Unit Prices'!D14 -> cuplock Vertical 2M | I14: =SUM(F14:H14) -> 0 | J14: =E14-I14 -> 0 | P14: =SUM(M14:O14) -> 0
A15: 7 | B15: ='Unit Prices'!B15 -> CK0025 | C15: ='Unit Prices'!C15 -> 14.80.02.19.06.23.00.000001 | D15: ='Unit Prices'!D15 -> cuplock Vertical 2.3M | I15: =SUM(F15:H15) -> 0 | J15: =E15-I15 -> 0 | P15: =SUM(M15:O15) -> 0
A16: 8 | B16: ='Unit Prices'!B16 -> CK0026 | C16: ='Unit Prices'!C16 -> 14.80.02.19.06.25.00.000001 | D16: ='Unit Prices'!D16 -> cuplock Vertical 2.5M | I16: =SUM(F16:H16) -> 0 | J16: =E16-I16 -> 0 | P16: =SUM(M16:O16) -> 0
A17: 9 | B17: ='Unit Prices'!B17 -> CK0027 | C17: ='Unit Prices'!C17 -> 14.80.02.19.06.28.00.000001 | D17: ='Unit Prices'!D17 -> cuplock Vertical 2.8M | I17: =SUM(F17:H17) -> 0 | J17: =E17-I17 -> 0 | P17: =SUM(M17:O17) -> 0
A18: 10 | B18: ='Unit Prices'!B18 -> CK0020 | C18: ='Unit Prices'!C18 -> 14.80.02.19.06.03.00.000001 | D18: ='Unit Prices'!D18 -> cuplock Vertical 3M | I18: =SUM(F18:H18) -> 0 | J18: =E18-I18 -> 0 | P18: =SUM(M18:O18) -> 0
A19: 11 | B19: ='Unit Prices'!B19 -> CL0001 | C19: ='Unit Prices'!C19 -> 14.80.50.24.01.00.00.000001 | D19: ='Unit Prices'!D19 -> cuplock Spigot | I19: =SUM(F19:H19) -> 0 | J19: =E19-I19 -> 0 | P19: =SUM(M19:O19) -> 0
A20: 12 | B20: ='Unit Prices'!B20 -> CK0006 | C20: ='Unit Prices'!C20 -> 14.80.02.19.04.04.00.000001 | D20: ='Unit Prices'!D20 -> cuplock Ledger 0.4M | I20: =SUM(F20:H20) -> 0 | J20: =E20-I20 -> 0 | P20: =SUM(M20:O20) -> 0
... A758: 750 | B758: ='Unit Prices'!B758 -> 0 | C758: ='Unit Prices'!C758 -> 0 | D758: ='Unit Prices'!D758 -> #N/A | I758: =SUM(F758:H758) -> 0 | J758: =E758-I758 -> 0 | P758: =SUM(M758:O758) -> 0

Sheet PR-0007
A1: Project Name: | D1: Slab | E1: 0 | F1: =$C$6*E1 -> 0 | I1: =E1 -> 0 | J1: =E1 -> 0 | P1: =I1 -> 0
D2: Walls and Colums | E2: 0 | F2: =$C$6*E2 -> 0 | I2: =E2 -> 0 | J2: =E2 -> 0 | P2: =I2 -> 0
A3: PR# No: | D3: Scaffolding | E3: 0 | F3: =$C$6*E3 -> 0 | I3: =E3 -> 0 | J3: =E3 -> 0 | P3: =I3 -> 0
A4: PR# Date: | D4: Safety | E4: 0 | F4: =$C$6*E4 -> 0 | I4: =E4 -> 0 | J4: =E4 -> 0 | M4: Return Qty | P4: =I4 -> 0
A5: PR# For: | D5: Recived/Transfer Date:
A6: Area: | D6: Store Voucher No:
A8: No | B8: ASSET CODE | C8: FULL SERIAL | D8: ITEMS NAME | E8: Req Qty | I8: Send Qty | J8: Remain Qty | K8: Remarks | P8: T.Return
A9: 1 | B9: ='Unit Prices'!B9 -> CK0021 | C9: ='Unit Prices'!C9 -> 14.80.02.19.06.05.00.000001 | D9: ='Unit Prices'!D9 -> cuplock Vertical 0.5M | I9: =SUM(F9:H9) -> 0 | J9: =E9-I9 -> 0 | P9: =SUM(M9:O9) -> 0
A10: 2 | B10: ='Unit Prices'!B10 -> CK0018 | C10: ='Unit Prices'!C10 -> 14.80.02.19.06.01.00.000001 | D10: ='Unit Prices'!D10 -> cuplock Vertical 1M | I10: =SUM(F10:H10) -> 0 | J10: =E10-I10 -> 0 | P10: =SUM(M10:O10) -> 0
A11: 3 | B11: ='Unit Prices'!B11 -> CK0022 | C11: ='Unit Prices'!C11 -> 14.80.02.19.06.13.00.000001 | D11: ='Unit Prices'!D11 -> cuplock Vertical 1.3M | I11: =SUM(F11:H11) -> 0 | J11: =E11-I11 -> 0 | P11: =SUM(M11:O11) -> 0
A12: 4 | B12: ='Unit Prices'!B12 -> CK0023 | C12: ='Unit Prices'!C12 -> 14.80.02.19.06.15.00.000001 | D12: ='Unit Prices'!D12 -> cuplock Vertical 1.5M | I12: =SUM(F12:H12) -> 0 | J12: =E12-I12 -> 0 | P12: =SUM(M12:O12) -> 0
A13: 5 | B13: ='Unit Prices'!B13 -> CK0024 | C13: ='Unit Prices'!C13 -> 14.80.02.19.06.18.00.000001 | D13: ='Unit Prices'!D13 -> cuplock Vertical 1.8M | I13: =SUM(F13:H13) -> 0 | J13: =E13-I13 -> 0 | P13: =SUM(M13:O13) -> 0
A14: 6 | B14: ='Unit Prices'!B14 -> CK0019 | C14: ='Unit Prices'!C14 -> 14.80.02.19.06.02.00.000001 | D14: ='Unit Prices'!D14 -> cuplock Vertical 2M | I14: =SUM(F14:H14) -> 0 | J14: =E14-I14 -> 0 | P14: =SUM(M14:O14) -> 0
A15: 7 | B15: ='Unit Prices'!B15 -> CK0025 | C15: ='Unit Prices'!C15 -> 14.80.02.19.06.23.00.000001 | D15: ='Unit Prices'!D15 -> cuplock Vertical 2.3M | I15: =SUM(F15:H15) -> 0 | J15: =E15-I15 -> 0 | P15: =SUM(M15:O15) -> 0
A16: 8 | B16: ='Unit Prices'!B16 -> CK0026 | C16: ='Unit Prices'!C16 -> 14.80.02.19.06.25.00.000001 | D16: ='Unit Prices'!D16 -> cuplock Vertical 2.5M | I16: =SUM(F16:H16) -> 0 | J16: =E16-I16 -> 0 | P16: =SUM(M16:O16) -> 0
A17: 9 | B17: ='Unit Prices'!B17 -> CK0027 | C17: ='Unit Prices'!C17 -> 14.80.02.19.06.28.00.000001 | D17: ='Unit Prices'!D17 -> cuplock Vertical 2.8M | I17: =SUM(F17:H17) -> 0 | J17: =E17-I17 -> 0 | P17: =SUM(M17:O17) -> 0
A18: 10 | B18: ='Unit Prices'!B18 -> CK0020 | C18: ='Unit Prices'!C18 -> 14.80.02.19.06.03.00.000001 | D18: ='Unit Prices'!D18 -> cuplock Vertical 3M | I18: =SUM(F18:H18) -> 0 | J18: =E18-I18 -> 0 | P18: =SUM(M18:O18) -> 0
A19: 11 | B19: ='Unit Prices'!B19 -> CL0001 | C19: ='Unit Prices'!C19 -> 14.80.50.24.01.00.00.000001 | D19: ='Unit Prices'!D19 -> cuplock Spigot | I19: =SUM(F19:H19) -> 0 | J19: =E19-I19 -> 0 | P19: =SUM(M19:O19) -> 0
A20: 12 | B20: ='Unit Prices'!B20 -> CK0006 | C20: ='Unit Prices'!C20 -> 14.80.02.19.04.04.00.000001 | D20: ='Unit Prices'!D20 -> cuplock Ledger 0.4M | I20: =SUM(F20:H20) -> 0 | J20: =E20-I20 -> 0 | P20: =SUM(M20:O20) -> 0
... A758: 750 | B758: ='Unit Prices'!B758 -> 0 | C758: ='Unit Prices'!C758 -> 0 | D758: ='Unit Prices'!D758 -> #N/A | I758: =SUM(F758:H758) -> 0 | J758: =E758-I758 -> 0 | P758: =SUM(M758:O758) -> 0

Sheet PR-0008
A1: Project Name: | D1: Slab | E1: 0 | F1: =$C$6*E1 -> 0 | I1: =E1 -> 0 | J1: =E1 -> 0 | P1: =I1 -> 0
D2: Walls and Colums | E2: 0 | F2: =$C$6*E2 -> 0 | I2: =E2 -> 0 | J2: =E2 -> 0 | P2: =I2 -> 0
A3: PR# No: | D3: Scaffolding | E3: 0 | F3: =$C$6*E3 -> 0 | I3: =E3 -> 0 | J3: =E3 -> 0 | P3: =I3 -> 0
A4: PR# Date: | D4: Safety | E4: 0 | F4: =$C$6*E4 -> 0 | I4: =E4 -> 0 | J4: =E4 -> 0 | M4: Return Qty | P4: =I4 -> 0
A5: PR# For: | D5: Recived/Transfer Date:
A6: Area: | D6: Store Voucher No:
A8: No | B8: ASSET CODE | C8: FULL SERIAL | D8: ITEMS NAME | E8: Req Qty | I8: Send Qty | J8: Remain Qty | K8: Remarks | P8: T.Return
A9: 1 | B9: ='Unit Prices'!B9 -> CK0021 | C9: ='Unit Prices'!C9 -> 14.80.02.19.06.05.00.000001 | D9: ='Unit Prices'!D9 -> cuplock Vertical 0.5M | I9: =SUM(F9:H9) -> 0 | J9: =E9-I9 -> 0 | P9: =SUM(M9:O9) -> 0
A10: 2 | B10: ='Unit Prices'!B10 -> CK0018 | C10: ='Unit Prices'!C10 -> 14.80.02.19.06.01.00.000001 | D10: ='Unit Prices'!D10 -> cuplock Vertical 1M | I10: =SUM(F10:H10) -> 0 | J10: =E10-I10 -> 0 | P10: =SUM(M10:O10) -> 0
A11: 3 | B11: ='Unit Prices'!B11 -> CK0022 | C11: ='Unit Prices'!C11 -> 14.80.02.19.06.13.00.000001 | D11: ='Unit Prices'!D11 -> cuplock Vertical 1.3M | I11: =SUM(F11:H11) -> 0 | J11: =E11-I11 -> 0 | P11: =SUM(M11:O11) -> 0
A12: 4 | B12: ='Unit Prices'!B12 -> CK0023 | C12: ='Unit Prices'!C12 -> 14.80.02.19.06.15.00.000001 | D12: ='Unit Prices'!D12 -> cuplock Vertical 1.5M | I12: =SUM(F12:H12) -> 0 | J12: =E12-I12 -> 0 | P12: =SUM(M12:O12) -> 0
A13: 5 | B13: ='Unit Prices'!B13 -> CK0024 | C13: ='Unit Prices'!C13 -> 14.80.02.19.06.18.00.000001 | D13: ='Unit Prices'!D13 -> cuplock Vertical 1.8M | I13: =SUM(F13:H13) -> 0 | J13: =E13-I13 -> 0 | P13: =SUM(M13:O13) -> 0
A14: 6 | B14: ='Unit Prices'!B14 -> CK0019 | C14: ='Unit Prices'!C14 -> 14.80.02.19.06.02.00.000001 | D14: ='Unit Prices'!D14 -> cuplock Vertical 2M | I14: =SUM(F14:H14) -> 0 | J14: =E14-I14 -> 0 | P14: =SUM(M14:O14) -> 0
A15: 7 | B15: ='Unit Prices'!B15 -> CK0025 | C15: ='Unit Prices'!C15 -> 14.80.02.19.06.23.00.000001 | D15: ='Unit Prices'!D15 -> cuplock Vertical 2.3M | I15: =SUM(F15:H15) -> 0 | J15: =E15-I15 -> 0 | P15: =SUM(M15:O15) -> 0
A16: 8 | B16: ='Unit Prices'!B16 -> CK0026 | C16: ='Unit Prices'!C16 -> 14.80.02.19.06.25.00.000001 | D16: ='Unit Prices'!D16 -> cuplock Vertical 2.5M | I16: =SUM(F16:H16) -> 0 | J16: =E16-I16 -> 0 | P16: =SUM(M16:O16) -> 0
A17: 9 | B17: ='Unit Prices'!B17 -> CK0027 | C17: ='Unit Prices'!C17 -> 14.80.02.19.06.28.00.000001 | D17: ='Unit Prices'!D17 -> cuplock Vertical 2.8M | I17: =SUM(F17:H17) -> 0 | J17: =E17-I17 -> 0 | P17: =SUM(M17:O17) -> 0
A18: 10 | B18: ='Unit Prices'!B18 -> CK0020 | C18: ='Unit Prices'!C18 -> 14.80.02.19.06.03.00.000001 | D18: ='Unit Prices'!D18 -> cuplock Vertical 3M | I18: =SUM(F18:H18) -> 0 | J18: =E18-I18 -> 0 | P18: =SUM(M18:O18) -> 0
A19: 11 | B19: ='Unit Prices'!B19 -> CL0001 | C19: ='Unit Prices'!C19 -> 14.80.50.24.01.00.00.000001 | D19: ='Unit Prices'!D19 -> cuplock Spigot | I19: =SUM(F19:H19) -> 0 | J19: =E19-I19 -> 0 | P19: =SUM(M19:O19) -> 0
A20: 12 | B20: ='Unit Prices'!B20 -> CK0006 | C20: ='Unit Prices'!C20 -> 14.80.02.19.04.04.00.000001 | D20: ='Unit Prices'!D20 -> cuplock Ledger 0.4M | I20: =SUM(F20:H20) -> 0 | J20: =E20-I20 -> 0 | P20: =SUM(M20:O20) -> 0
... A758: 750 | B758: ='Unit Prices'!B758 -> 0 | C758: ='Unit Prices'!C758 -> 0 | D758: ='Unit Prices'!D758 -> #N/A | I758: =SUM(F758:H758) -> 0 | J758: =E758-I758 -> 0 | P758: =SUM(M758:O758) -> 0

Sheet PR-0009
A1: Project Name: | D1: Slab | E1: 0 | F1: =$C$6*E1 -> 0 | I1: =E1 -> 0 | J1: =E1 -> 0 | P1: =I1 -> 0
D2: Walls and Colums | E2: 0 | F2: =$C$6*E2 -> 0 | I2: =E2 -> 0 | J2: =E2 -> 0 | P2: =I2 -> 0
A3: PR# No: | D3: Scaffolding | E3: 0 | F3: =$C$6*E3 -> 0 | I3: =E3 -> 0 | J3: =E3 -> 0 | P3: =I3 -> 0
A4: PR# Date: | D4: Safety | E4: 0 | F4: =$C$6*E4 -> 0 | I4: =E4 -> 0 | J4: =E4 -> 0 | M4: Return Qty | P4: =I4 -> 0
A5: PR# For: | D5: Recived/Transfer Date:
A6: Area: | D6: Store Voucher No:
A8: No | B8: ASSET CODE | C8: FULL SERIAL | D8: ITEMS NAME | E8: Req Qty | I8: Send Qty | J8: Remain Qty | K8: Remarks | P8: T.Return
A9: 1 | B9: ='Unit Prices'!B9 -> CK0021 | C9: ='Unit Prices'!C9 -> 14.80.02.19.06.05.00.000001 | D9: ='Unit Prices'!D9 -> cuplock Vertical 0.5M | I9: =SUM(F9:H9) -> 0 | J9: =E9-I9 -> 0 | P9: =SUM(M9:O9) -> 0
A10: 2 | B10: ='Unit Prices'!B10 -> CK0018 | C10: ='Unit Prices'!C10 -> 14.80.02.19.06.01.00.000001 | D10: ='Unit Prices'!D10 -> cuplock Vertical 1M | I10: =SUM(F10:H10) -> 0 | J10: =E10-I10 -> 0 | P10: =SUM(M10:O10) -> 0
A11: 3 | B11: ='Unit Prices'!B11 -> CK0022 | C11: ='Unit Prices'!C11 -> 14.80.02.19.06.13.00.000001 | D11: ='Unit Prices'!D11 -> cuplock Vertical 1.3M | I11: =SUM(F11:H11) -> 0 | J11: =E11-I11 -> 0 | P11: =SUM(M11:O11) -> 0
A12: 4 | B12: ='Unit Prices'!B12 -> CK0023 | C12: ='Unit Prices'!C12 -> 14.80.02.19.06.15.00.000001 | D12: ='Unit Prices'!D12 -> cuplock Vertical 1.5M | I12: =SUM(F12:H12) -> 0 | J12: =E12-I12 -> 0 | P12: =SUM(M12:O12) -> 0
A13: 5 | B13: ='Unit Prices'!B13 -> CK0024 | C13: ='Unit Prices'!C13 -> 14.80.02.19.06.18.00.000001 | D13: ='Unit Prices'!D13 -> cuplock Vertical 1.8M | I13: =SUM(F13:H13) -> 0 | J13: =E13-I13 -> 0 | P13: =SUM(M13:O13) -> 0
A14: 6 | B14: ='Unit Prices'!B14 -> CK0019 | C14: ='Unit Prices'!C14 -> 14.80.02.19.06.02.00.000001 | D14: ='Unit Prices'!D14 -> cuplock Vertical 2M | I14: =SUM(F14:H14) -> 0 | J14: =E14-I14 -> 0 | P14: =SUM(M14:O14) -> 0
A15: 7 | B15: ='Unit Prices'!B15 -> CK0025 | C15: ='Unit Prices'!C15 -> 14.80.02.19.06.23.00.000001 | D15: ='Unit Prices'!D15 -> cuplock Vertical 2.3M | I15: =SUM(F15:H15) -> 0 | J15: =E15-I15 -> 0 | P15: =SUM(M15:O15) -> 0
A16: 8 | B16: ='Unit Prices'!B16 -> CK0026 | C16: ='Unit Prices'!C16 -> 14.80.02.19.06.25.00.000001 | D16: ='Unit Prices'!D16 -> cuplock Vertical 2.5M | I16: =SUM(F16:H16) -> 0 | J16: =E16-I16 -> 0 | P16: =SUM(M16:O16) -> 0
A17: 9 | B17: ='Unit Prices'!B17 -> CK0027 | C17: ='Unit Prices'!C17 -> 14.80.02.19.06.28.00.000001 | D17: ='Unit Prices'!D17 -> cuplock Vertical 2.8M | I17: =SUM(F17:H17) -> 0 | J17: =E17-I17 -> 0 | P17: =SUM(M17:O17) -> 0
A18: 10 | B18: ='Unit Prices'!B18 -> CK0020 | C18: ='Unit Prices'!C18 -> 14.80.02.19.06.03.00.000001 | D18: ='Unit Prices'!D18 -> cuplock Vertical 3M | I18: =SUM(F18:H18) -> 0 | J18: =E18-I18 -> 0 | P18: =SUM(M18:O18) -> 0
A19: 11 | B19: ='Unit Prices'!B19 -> CL0001 | C19: ='Unit Prices'!C19 -> 14.80.50.24.01.00.00.000001 | D19: ='Unit Prices'!D19 -> cuplock Spigot | I19: =SUM(F19:H19) -> 0 | J19: =E19-I19 -> 0 | P19: =SUM(M19:O19) -> 0
A20: 12 | B20: ='Unit Prices'!B20 -> CK0006 | C20: ='Unit Prices'!C20 -> 14.80.02.19.04.04.00.000001 | D20: ='Unit Prices'!D20 -> cuplock Ledger 0.4M | I20: =SUM(F20:H20) -> 0 | J20: =E20-I20 -> 0 | P20: =SUM(M20:O20) -> 0
... A758: 750 | B758: ='Unit Prices'!B758 -> 0 | C758: ='Unit Prices'!C758 -> 0 | D758: ='Unit Prices'!D758 -> #N/A | I758: =SUM(F758:H758) -> 0 | J758: =E758-I758 -> 0 | P758: =SUM(M758:O758) -> 0

Sheet PR-0010
A1: Project Name: | D1: Slab | E1: 0 | F1: =$C$6*E1 -> 0 | I1: =E1 -> 0 | J1: =E1 -> 0 | P1: =I1 -> 0
D2: Walls and Colums | E2: 0 | F2: =$C$6*E2 -> 0 | I2: =E2 -> 0 | J2: =E2 -> 0 | P2: =I2 -> 0
A3: PR# No: | D3: Scaffolding | E3: 0 | F3: =$C$6*E3 -> 0 | I3: =E3 -> 0 | J3: =E3 -> 0 | P3: =I3 -> 0
A4: PR# Date: | D4: Safety | E4: 0 | F4: =$C$6*E4 -> 0 | I4: =E4 -> 0 | J4: =E4 -> 0 | M4: Return Qty | P4: =I4 -> 0
A5: PR# For: | D5: Recived/Transfer Date:
A6: Area: | D6: Store Voucher No:
A8: No | B8: ASSET CODE | C8: FULL SERIAL | D8: ITEMS NAME | E8: Req Qty | I8: Send Qty | J8: Remain Qty | K8: Remarks | P8: T.Return
A9: 1 | B9: ='Unit Prices'!B9 -> CK0021 | C9: ='Unit Prices'!C9 -> 14.80.02.19.06.05.00.000001 | D9: ='Unit Prices'!D9 -> cuplock Vertical 0.5M | I9: =SUM(F9:H9) -> 0 | J9: =E9-I9 -> 0 | P9: =SUM(M9:O9) -> 0
A10: 2 | B10: ='Unit Prices'!B10 -> CK0018 | C10: ='Unit Prices'!C10 -> 14.80.02.19.06.01.00.000001 | D10: ='Unit Prices'!D10 -> cuplock Vertical 1M | I10: =SUM(F10:H10) -> 0 | J10: =E10-I10 -> 0 | P10: =SUM(M10:O10) -> 0
A11: 3 | B11: ='Unit Prices'!B11 -> CK0022 | C11: ='Unit Prices'!C11 -> 14.80.02.19.06.13.00.000001 | D11: ='Unit Prices'!D11 -> cuplock Vertical 1.3M | I11: =SUM(F11:H11) -> 0 | J11: =E11-I11 -> 0 | P11: =SUM(M11:O11) -> 0
A12: 4 | B12: ='Unit Prices'!B12 -> CK0023 | C12: ='Unit Prices'!C12 -> 14.80.02.19.06.15.00.000001 | D12: ='Unit Prices'!D12 -> cuplock Vertical 1.5M | I12: =SUM(F12:H12) -> 0 | J12: =E12-I12 -> 0 | P12: =SUM(M12:O12) -> 0
A13: 5 | B13: ='Unit Prices'!B13 -> CK0024 | C13: ='Unit Prices'!C13 -> 14.80.02.19.06.18.00.000001 | D13: ='Unit Prices'!D13 -> cuplock Vertical 1.8M | I13: =SUM(F13:H13) -> 0 | J13: =E13-I13 -> 0 | P13: =SUM(M13:O13) -> 0
A14: 6 | B14: ='Unit Prices'!B14 -> CK0019 | C14: ='Unit Prices'!C14 -> 14.80.02.19.06.02.00.000001 | D14: ='Unit Prices'!D14 -> cuplock Vertical 2M | I14: =SUM(F14:H14) -> 0 | J14: =E14-I14 -> 0 | P14: =SUM(M14:O14) -> 0
A15: 7 | B15: ='Unit Prices'!B15 -> CK0025 | C15: ='Unit Prices'!C15 -> 14.80.02.19.06.23.00.000001 | D15: ='Unit Prices'!D15 -> cuplock Vertical 2.3M | I15: =SUM(F15:H15) -> 0 | J15: =E15-I15 -> 0 | P15: =SUM(M15:O15) -> 0
A16: 8 | B16: ='Unit Prices'!B16 -> CK0026 | C16: ='Unit Prices'!C16 -> 14.80.02.19.06.25.00.000001 | D16: ='Unit Prices'!D16 -> cuplock Vertical 2.5M | I16: =SUM(F16:H16) -> 0 | J16: =E16-I16 -> 0 | P16: =SUM(M16:O16) -> 0
A17: 9 | B17: ='Unit Prices'!B17 -> CK0027 | C17: ='Unit Prices'!C17 -> 14.80.02.19.06.28.00.000001 | D17: ='Unit Prices'!D17 -> cuplock Vertical 2.8M | I17: =SUM(F17:H17) -> 0 | J17: =E17-I17 -> 0 | P17: =SUM(M17:O17) -> 0
A18: 10 | B18: ='Unit Prices'!B18 -> CK0020 | C18: ='Unit Prices'!C18 -> 14.80.02.19.06.03.00.000001 | D18: ='Unit Prices'!D18 -> cuplock Vertical 3M | I18: =SUM(F18:H18) -> 0 | J18: =E18-I18 -> 0 | P18: =SUM(M18:O18) -> 0
A19: 11 | B19: ='Unit Prices'!B19 -> CL0001 | C19: ='Unit Prices'!C19 -> 14.80.50.24.01.00.00.000001 | D19: ='Unit Prices'!D19 -> cuplock Spigot | I19: =SUM(F19:H19) -> 0 | J19: =E19-I19 -> 0 | P19: =SUM(M19:O19) -> 0
A20: 12 | B20: ='Unit Prices'!B20 -> CK0006 | C20: ='Unit Prices'!C20 -> 14.80.02.19.04.04.00.000001 | D20: ='Unit Prices'!D20 -> cuplock Ledger 0.4M | I20: =SUM(F20:H20) -> 0 | J20: =E20-I20 -> 0 | P20: =SUM(M20:O20) -> 0
... A758: 750 | B758: ='Unit Prices'!B758 -> 0 | C758: ='Unit Prices'!C758 -> 0 | D758: ='Unit Prices'!D758 -> #N/A | I758: =SUM(F758:H758) -> 0 | J758: =E758-I758 -> 0 | P758: =SUM(M758:O758) -> 0

Sheet Total
E6: SLAB | J6: WALLS & COLUMNS | O6: SCAFFOLDIN | T6: SAFETY | Z6: Total Summary
E7: Area= | F7: ='9400015894 PONEERS'!F1+'9400016451 VIDAFORM'!F1+'PO 94000171374 MASTER'!F1+'PR-0004'!F1+'PR-0005'!F1+'PR-0006'!F1+'PR-0007'!F1+'PR-0008'!F1+'PR-0009'!F1+'PR-0010'!F1 -> 0 | J7: Area= | K7: ='9400015894 PONEERS'!F2+'9400016451 VIDAFORM'!F2+'PO 94000171374 MASTER'!F2+'PR-0004'!F2+'PR-0005'!F2+'PR-0006'!F2+'PR-0007'!F2+'PR-0008'!F2+'PR-0009'!F2+'PR-0010'!F2 -> 0 | O7: Area= | P7: ='9400015894 PONEERS'!F3+'9400016451 VIDAFORM'!F3+'PO 94000171374 MASTER'!F3+'PR-0004'!F3+'PR-0005'!F3+'PR-0006'!F3+'PR-0007'!F3+'PR-0008'!F3+'PR-0009'!F3+'PR-0010'!F3 -> 0 | T7: Area= | U7: ='9400015894 PONEERS'!F4+'9400016451 VIDAFORM'!F4+'PO 94000171374 MASTER'!F4+'PR-0004'!F4+'PR-0005'!F4+'PR-0006'!F4+'PR-0007'!F4+'PR-0008'!F4+'PR-0009'!F4+'PR-0010'!F4 -> 0
A8: No | B8: ASSET CODE | C8: FULL SERIAL | D8: ITEMS NAME | E8: REQ | F8: SEND | G8: REMAIN | H8: Return Qty | I8: Ava Qty | J8: REQ | K8: SEND | L8: REMAIN | M8: Return Qty | N8: Ava Qty | O8: REQ | P8: SEND | Q8: REMAIN | R8: Return Qty | S8: Ava Qty | T8: REQ | U8: SEND | V8: REMAIN | W8: Return Qty | X8: Ava Qty | Z8: T. REQ | AA8: T. SEND | AB8: T. REMAIN
